Workbook
Name Données: DONNÉES!$A$1:$N$65
Name SectionÉpicerie: OPTIONS!$F$2:$F$8

Sheet DIRECTIVES
B2: Directives d'utilisation du fichier MENU et QUANTITÉS
B3: L'objectif de ce fichier est de structurer l'élaboration d'un menu. Il contient aussi une base de données de plats précédents afin de donner de l'inspiration et une base.
B5: Onglet BIBLIOTHÈQUE
B6: Cet onglet constitue une base de données d'items de menu précédent. Il peut servir à générer des idées pour un repas ou comme point de départ pour établir des quantités. Il est possible que plusieurs items se répètent dans cet onglet. Il ne faut pas se fier aveuglément aux informations disponibles dans cet onglet (quantité, mesure, section, etc.). Il faut toujours réviser les données utilisées pour son menu.
B8: ONGLETS À MODIFIER
B9: Onglet OPTIONS
B10: Dans cet onglet, il faut indiquer les dates correspondantes au camp, ainsi que le nombre de personnes à chaque moment. Le chiffre correspondant à la date sera utilisé dans l'onglet DONNÉES. "0" MOYENNE peut servir à identifier des aliments qui seront utilisés tout le temps. Il est possible d'avoir deux fois la même date avec des chiffres de journée différents pour indiquer un nombre de personnes différent à la même journée. (Ex. Des parents rejoignent le camp pour le diner avant le départ)
B11: Onglet DONNÉES
B12: C'est l'onglet principal à remplir. Toutes les colonnes bleues (pâles et foncé) doivent être remplies. Il est possible de les copier directement de l'onglet Bibliothèque, mais il faut les réviser. SECTION indique l'emplacement dans l'épicerie, il y a une liste déroulante pour assurer une utilisation uniforme, cependant, il est possible d'ajouter des choix à la liste déroulante dans l'onglet OPTIONS PORTION 1 indique une portion individuelle; MESURE indique l'unité de mesure utilisée pour la portion (il faut être le plus représentatif possible); CENTRE? Indique si l'ingrédient est mis de côté au centre (OUI/NON), ÉPICERIE indique ou et/ou à quel moment l'achat sera fait. Il est possible de forcer des quantités fixes peu importe le nombre de personnes (voir en exemple la formule utilisée dans la cellule portion pour 1 boîte de sel)
B13: Onglet INVENTAIRE CENTRE
B14: Cet onglet sert à énumérer les aliments disponibles et mis de côté au centre. Des directives additionnelles se retrouvent déjà dans l'onglet.
B15: Onglet MENU VISUEL
... B22: Cet onglet consolide les données afin de montrer les différentes listes d'épicerie et les quantités de façon structurée et par section. Il doit être ajusté par les filtres afin de montrer l'information souhaitée. Pour le mettre à jour il faut rafraîchir les données des tableaux croisés dynamiques dans l'onglet Analyser.
C25: VERSION | D25: DATE | E25: MODIFIÉ PAR
C26: 1 | D26: 42979 | E26: Robert S.
C27: 2 | D27: 43374 | E27: Marc S.

Sheet BIBLIOTHÈQUE
A1: ID RECHERCHE | B1: CATÉGORIE | C1: PLAT | D1: INGRÉDIENT | E1: SECTION | F1: PORTION 1 | G1: MESURE
A2: =CONCATENATE(B2,"/",C2) -> 0. Autre/Sucre | B2: 0. Autre | C2: Sucre | D2: Sucre | E2: Varia | F2: 0.010309278 | G2: Boîte
A3: =CONCATENATE(B3,"/",C3) -> 0. Autre/Sel | B3: 0. Autre | C3: Sel | D3: Sel | E3: Varia | F3: 0.010309278 | G3: Boîte
A4: =CONCATENATE(B4,"/",C4) -> 0. Autre/Poivre | B4: 0. Autre | C4: Poivre | D4: Poivre | E4: Varia | F4: 0.010309278 | G4: Boîte
A5: =CONCATENATE(B5,"/",C5) -> 0. Autre/Café instantané | B5: 0. Autre | C5: Café instantané | D5: Café instantané | E5: Varia | F5: 0.010309278 | G5: Boîte
A6: =CONCATENATE(B6,"/",C6) -> 1. Déjeuner/Yogourt Grec | B6: 1. Déjeuner | C6: Yogourt Grec | D6: Yogourt grec (individuel) | E6: Produits laitiers | F6: 1 | G6: Unité
A7: =CONCATENATE(B7,"/",C7) -> 1. Déjeuner/Toasts et confiture | B7: 1. Déjeuner | C7: Toasts et confiture | D7: Toasts | E7: Produits laitiers | F7: 2 | G7: unité
A8: =CONCATENATE(B8,"/",C8) -> 1. Déjeuner/Toasts et confiture | B8: 1. Déjeuner | C8: Toasts et confiture | D8: Confiture | E8: Varia | F8: 0.010309278 | G8: Gros pot
A9: =CONCATENATE(B9,"/",C9) -> 1. Déjeuner/Toasts | B9: 1. Déjeuner | C9: Toasts | D9: Toasts | E9: Produits céréaliers | F9: 3 | G9: Unité
A10: =CONCATENATE(B10,"/",C10) -> 1. Déjeuner/Toasts | B10: 1. Déjeuner | C10: Toasts | D10: Peanut butter | E10: Varia | F10: 20 | G10: ml
A11: =CONCATENATE(B11,"/",C11) -> 1. Déjeuner/Toasts | B11: 1. Déjeuner | C11: Toasts | D11: Nutella | E11: Varia | F11: 20 | G11: ml
A12: =CONCATENATE(B12,"/",C12) -> 1. Déjeuner/Toasts | B12: 1. Déjeuner | C12: Toasts | D12: Confiture | E12: Varia | F12: 20 | G12: ml
A13: =CONCATENATE(B13,"/",C13) -> 1. Déjeuner/Toasts | B13: 1. Déjeuner | C13: Toasts | D13: Bananes | E13: Fruits et légumes | F13: 0.5 | G13: Unité
A14: =CONCATENATE(B14,"/",C14) -> 1. Déjeuner/Toast/gaufre nutella/peanut | B14: 1. Déjeuner | C14: Toast/gaufre nutella/peanut | D14: Toasts | E14: Produits céréaliers | F14: 1 | G14: Unité
A15: =CONCATENATE(B15,"/",C15) -> 1. Déjeuner/Toast/gaufre nutella/peanut | B15: 1. Déjeuner | C15: Toast/gaufre nutella/peanut | D15: Peanut butter | E15: Varia | F15: 20 | G15: ml
A16: =CONCATENATE(B16,"/",C16) -> 1. Déjeuner/Toast/gaufre nutella/peanut | B16: 1. Déjeuner | C16: Toast/gaufre nutella/peanut | D16: Nutella | E16: Varia | F16: 20 | G16: ml
A17: =CONCATENATE(B17,"/",C17) -> 1. Déjeuner/Toast/gaufre nutella/peanut | B17: 1. Déjeuner | C17: Toast/gaufre nutella/peanut | D17: Gaufre | E17: Produits céréaliers | F17: 1 | G17: Unité
A18: =CONCATENATE(B18,"/",C18) -> 1. Déjeuner/Toast/gaufre nutella/peanut | B18: 1. Déjeuner | C18: Toast/gaufre nutella/peanut | D18: Banane | E18: Fruits et légumes | F18: 0.5 | G18: Unité
A19: =CONCATENATE(B19,"/",C19) -> 1. Déjeuner/Toast/gaufre nutella/peanut | B19: 1. Déjeuner | C19: Toast/gaufre nutella/peanut | D19: Fraises | E19: Fruits et légumes | F19: 4 | G19: Unité
A20: =CONCATENATE(B20,"/",C20) -> 1. Déjeuner/Toast/gaufre nutella/peanut | B20: 1. Déjeuner | C20: Toast/gaufre nutella/peanut | D20: Sirop d'érable | E20: Varia | F20: 40 | G20: ml
A21: =CONCATENATE(B21,"/",C21) -> 1. Déjeuner/Toast/gaufre nutella/peanut | B21: 1. Déjeuner | C21: Toast/gaufre nutella/peanut | D21: Lait | E21: Produits laitiers | F21: 235 | G21: ml
A22: =CONCATENATE(B22,"/",C22) -> 1. Déjeuner/Toast/gaufre nutella/peanut | B22: 1. Déjeuner | C22: Toast/gaufre nutella/peanut | D22: Froot loops | E22: Produits céréaliers | F22: 40 | G22: g
A23: =CONCATENATE(B23,"/",C23) -> yujuuu/Toast/gaufre nutella/peanut | B23: yujuuu | C23: Toast/gaufre nutella/peanut | D23: Cheerios | E23: Produits céréaliers | F23: 40 | G23: g
A24: =CONCATENATE(B24,"/",C24) -> 1. Déjeuner/Toast et Fruits | B24: 1. Déjeuner | C24: Toast et Fruits | D24: Pain toast | E24: Produits céréaliers | F24: 3 | G24: unité
A25: =CONCATENATE(B25,"/",C25) -> 1. Déjeuner/Toast et Fruits | B25: 1. Déjeuner | C25: Toast et Fruits | D25: Nutella | E25: Varia | F25: 30 | G25: g
A26: =CONCATENATE(B26,"/",C26) -> 1. Déjeuner/Toast et Fruits | B26: 1. Déjeuner | C26: Toast et Fruits | D26: Peanut Butter | E26: Varia | F26: 15 | G26: g
A27: =CONCATENATE(B27,"/",C27) -> 1. Déjeuner/Toast et Fruits | B27: 1. Déjeuner | C27: Toast et Fruits | D27: Bananes | E27: Fruits et légumes | F27: 1 | G27: unité
A28: =CONCATENATE(B28,"/",C28) -> 1. Déjeuner/Thé | B28: 1. Déjeuner | C28: Thé | D28: Thé | E28: Varia | F28: 10 | G28: Sachet
A29: =CONCATENATE(B29,"/",C29) -> 1. Déjeuner/Saucisses déjeuner | B29: 1. Déjeuner | C29: Saucisses déjeuner | D29: Saucisses déjeuner | E29: Viandes | F29: 50 | G29: gr
A30: =CONCATENATE(B30,"/",C30) -> 1. Déjeuner/Sandwich matin | B30: 1. Déjeuner | C30: Sandwich matin | D30: Toasts | E30: Produits céréaliers | F30: 3 | G30: Unité
... A67: =CONCATENATE(B67,"/",C67) -> 1. Déjeuner/Omelette | B67: 1. Déjeuner | C67: Omelette | D67: Jambon | E67: Viandes | F67: 20 | G67: gr
A68: =CONCATENATE(B68,"/",C68) -> 1. Déjeuner/Omelette | B68: 1. Déjeuner | C68: Omelette | D68: Oignon rouge | E68: Fruits et légumes | F68: 0.25 | G68: Unité
A69: =CONCATENATE(B69,"/",C69) -> 1. Déjeuner/Omelette | B69: 1. Déjeuner | C69: Omelette | D69: Piment | E69: Fruits et légumes | F69: 0.25 | G69: Unité
A70: =CONCATENATE(B70,"/",C70) -> 1. Déjeuner/Omelette | B70: 1. Déjeuner | C70: Omelette | D70: Toast | E70: Produits céréaliers | F70: 2 | G70: Unité
A71: =CONCATENATE(B71,"/",C71) -> 1. Déjeuner/Omelette | B71: 1. Déjeuner | C71: Omelette | D71: Lait | E71: Produits laitiers | F71: 235 | G71: ml
A72: =CONCATENATE(B72,"/",C72) -> 1. Déjeuner/Omelette | B72: 1. Déjeuner | C72: Omelette | D72: Sel | E72: Varia | F72: 1 | G72: g
A73: =CONCATENATE(B73,"/",C73) -> 1. Déjeuner/Omelette | B73: 1. Déjeuner | C73: Omelette | D73: Huile d'olive | E73: Varia | F73: 10 | G73: ml
A74: =CONCATENATE(B74,"/",C74) -> 1. Déjeuner/Œufs durs | B74: 1. Déjeuner | C74: Œufs durs | D74: Œufs | E74: Produits laitiers | F74: 1.2 | G74: unité
A75: =CONCATENATE(B75,"/",C75) -> 1. Déjeuner/Œufs brouillis | B75: 1. Déjeuner | C75: Œufs brouillis | D75: Œufs | E75: Produits laitiers | F75: 3 | G75: unité
A76: =CONCATENATE(B76,"/",C76) -> 1. Déjeuner/Œufs brouillis | B76: 1. Déjeuner | C76: Œufs brouillis | D76: Huile végétale | E76: Varia | F76: 2 | G76: ml
...

Sheet OPTIONS
A1: JOURNÉE | B1: DATE | C1: # PERSONNES | F1: SECTION D'ÉPICERIE
A2: 0 | B2: MOYENNE | C2: 31 | F2: Fruits et légumes
A3: 1 | B3: 45656 | C3: =$C$2 -> 31 | F3: Produits céréaliers
A4: 2 | B4: =B3+1 -> 45657 | C4: =$C$2 -> 31 | F4: Produits laitiers
A5: 3 | B5: =B4+1 -> 45658 | C5: =$C$2 -> 31 | F5: Varia
A6: 4 | B6: =B5+1 -> 45659 | C6: 96 | F6: Viandes
A7: 5 | B7: =B6+1 -> 45660 | C7: =$C$2 -> 31 | G7: *Il est possible d'ajouter des nouvelles sections ici
A8: 6 | B8: =B7+1 -> 45661 | C8: =$C$2 -> 31

Sheet DONNÉES
A1: JOURNÉE | B1: DATE | C1: REPAS | D1: PLAT | E1: INGRÉDIENT | F1: SECTION | G1: PORTION 1 | H1: MESURE | I1: CENTRE? | J1: ÉPICERIE? | K1: =CONCATENATE("PORTION GROUPE") -> PORTION GROUPE | L1: PAR PERSONNE | M1: POUR GROUPE | N1: INGRÉDIENT (PIV)
A2: 0 | B2: =VLOOKUP(A2,OPTIONS!A:C,2,FALSE) -> MOYENNE | C2: 0. Autre | D2: Sucre | E2: Sucre | F2: Varia | G2: =1/VLOOKUP(A2,OPTIONS!A:C,3,FALSE) -> 0.032258065 | H2: Boîte | K2: =VLOOKUP(A2,OPTIONS!A:C,3,FALSE)*G2 -> 1 | L2: =TRIM(CONCATENATE(G2," ", $H2, " ", $E2)) -> 0.032258064516129 Boîte Sucre | M2: =TRIM(CONCATENATE(K2," ", $H2, " ", $E2)) -> 1 Boîte Sucre | N2: =CONCATENATE(E2, " (", TRIM(H2), ")") -> Sucre (Boîte)
A3: 0 | B3: =VLOOKUP(A3,OPTIONS!A:C,2,FALSE) -> MOYENNE | C3: 0. Autre | D3: Sel | E3: Sel | F3: Varia | G3: =1/VLOOKUP(A3,OPTIONS!A:C,3,FALSE) -> 0.032258065 | H3: Boîte | K3: =VLOOKUP(A3,OPTIONS!A:C,3,FALSE)*G3 -> 1 | L3: =TRIM(CONCATENATE(G3," ", $H3, " ", $E3)) -> 0.032258064516129 Boîte Sel | M3: =TRIM(CONCATENATE(K3," ", $H3, " ", $E3)) -> 1 Boîte Sel | N3: =CONCATENATE(E3, " (", TRIM(H3), ")") -> Sel (Boîte)
A4: 0 | B4: =VLOOKUP(A4,OPTIONS!A:C,2,FALSE) -> MOYENNE | C4: 0. Autre | D4: Poivre | E4: Poivre | F4: Varia | G4: =1/VLOOKUP(A4,OPTIONS!A:C,3,FALSE) -> 0.032258065 | H4: Boîte | K4: =VLOOKUP(A4,OPTIONS!A:C,3,FALSE)*G4 -> 1 | L4: =TRIM(CONCATENATE(G4," ", $H4, " ", $E4)) -> 0.032258064516129 Boîte Poivre | M4: =TRIM(CONCATENATE(K4," ", $H4, " ", $E4)) -> 1 Boîte Poivre | N4: =CONCATENATE(E4, " (", TRIM(H4), ")") -> Poivre (Boîte)
A5: 0 | B5: =VLOOKUP(A5,OPTIONS!A:C,2,FALSE) -> MOYENNE | C5: 0. Autre | D5: Café instantané | E5: Café instantané | F5: Varia | G5: =1/VLOOKUP(A5,OPTIONS!A:C,3,FALSE) -> 0.032258065 | H5: Boîte | K5: =VLOOKUP(A5,OPTIONS!A:C,3,FALSE)*G5 -> 1 | L5: =TRIM(CONCATENATE(G5," ", $H5, " ", $E5)) -> 0.032258064516129 Boîte Café instantané | M5: =TRIM(CONCATENATE(K5," ", $H5, " ", $E5)) -> 1 Boîte Café instantané | N5: =CONCATENATE(E5, " (", TRIM(H5), ")") -> Café instantané (Boîte)
A6: 2 | B6: =VLOOKUP(A6,OPTIONS!A:C,2,FALSE) -> 45657 | C6: 2. Diner | D6: Charcuterie | E6: Jambon | F6: Viandes | G6: 30 | H6: g | K6: =VLOOKUP(A6,OPTIONS!A:C,3,FALSE)*G6 -> 930 | L6: =TRIM(CONCATENATE(G6," ", $H6, " ", $E6)) -> 30 g Jambon | M6: =TRIM(CONCATENATE(K6," ", $H6, " ", $E6)) -> 930 g Jambon | N6: =CONCATENATE(E6, " (", TRIM(H6), ")") -> Jambon (g)
A7: 2 | B7: =VLOOKUP(A7,OPTIONS!A:C,2,FALSE) -> 45657 | C7: 2. Diner | D7: Charcuterie | E7: Salami | F7: Viandes | G7: 30 | H7: g | K7: =VLOOKUP(A7,OPTIONS!A:C,3,FALSE)*G7 -> 930 | L7: =TRIM(CONCATENATE(G7," ", $H7, " ", $E7)) -> 30 g Salami | M7: =TRIM(CONCATENATE(K7," ", $H7, " ", $E7)) -> 930 g Salami | N7: =CONCATENATE(E7, " (", TRIM(H7), ")") -> Salami (g)
A8: 2 | B8: =VLOOKUP(A8,OPTIONS!A:C,2,FALSE) -> 45657 | C8: 2. Diner | D8: Charcuterie | E8: Mortadelle | F8: Viandes | G8: 30 | H8: g | K8: =VLOOKUP(A8,OPTIONS!A:C,3,FALSE)*G8 -> 930 | L8: =TRIM(CONCATENATE(G8," ", $H8, " ", $E8)) -> 30 g Mortadelle | M8: =TRIM(CONCATENATE(K8," ", $H8, " ", $E8)) -> 930 g Mortadelle | N8: =CONCATENATE(E8, " (", TRIM(H8), ")") -> Mortadelle (g)
A9: 2 | B9: =VLOOKUP(A9,OPTIONS!A:C,2,FALSE) -> 45657 | C9: 2. Diner | D9: Charcuterie | E9: Poulet | F9: Viandes | G9: 30 | H9: g | K9: =VLOOKUP(A9,OPTIONS!A:C,3,FALSE)*G9 -> 930 | L9: =TRIM(CONCATENATE(G9," ", $H9, " ", $E9)) -> 30 g Poulet | M9: =TRIM(CONCATENATE(K9," ", $H9, " ", $E9)) -> 930 g Poulet | N9: =CONCATENATE(E9, " (", TRIM(H9), ")") -> Poulet (g)
A10: 2 | B10: =VLOOKUP(A10,OPTIONS!A:C,2,FALSE) -> 45657 | C10: 2. Diner | D10: Chips | E10: Chips | F10: Varia | G10: 0.11111111 | H10: Sacs | K10: =VLOOKUP(A10,OPTIONS!A:C,3,FALSE)*G10 -> 3.4444444 | L10: =TRIM(CONCATENATE(G10," ", $H10, " ", $E10)) -> 0.111111111111111 Sacs Chips | M10: =TRIM(CONCATENATE(K10," ", $H10, " ", $E10)) -> 3.44444444444444 Sacs Chips | N10: =CONCATENATE(E10, " (", TRIM(H10), ")") -> Chips (Sacs)
A11: 1 | B11: =VLOOKUP(A11,OPTIONS!A:C,2,FALSE) -> 45656 | C11: 3. Souper | D11: Fajitas | E11: Tortillas | F11: Produits céréaliers | G11: 2.5 | H11: unité | K11: =VLOOKUP(A11,OPTIONS!A:C,3,FALSE)*G11 -> 77.5 | L11: =TRIM(CONCATENATE(G11," ", $H11, " ", $E11)) -> 2.5 unité Tortillas | M11: =TRIM(CONCATENATE(K11," ", $H11, " ", $E11)) -> 77.5 unité Tortillas | N11: =CONCATENATE(E11, " (", TRIM(H11), ")") -> Tortillas (unité)
A12: 1 | B12: =VLOOKUP(A12,OPTIONS!A:C,2,FALSE) -> 45656 | C12: 3. Souper | D12: Fajitas | E12: Poulet en lanières | F12: Viandes | G12: 170 | H12: g | K12: =VLOOKUP(A12,OPTIONS!A:C,3,FALSE)*G12 -> 5270 | L12: =TRIM(CONCATENATE(G12," ", $H12, " ", $E12)) -> 170 g Poulet en lanières | M12: =TRIM(CONCATENATE(K12," ", $H12, " ", $E12)) -> 5270 g Poulet en lanières | N12: =CONCATENATE(E12, " (", TRIM(H12), ")") -> Poulet en lanières (g)
A13: 1 | B13: =VLOOKUP(A13,OPTIONS!A:C,2,FALSE) -> 45656 | C13: 3. Souper | D13: Fajitas | E13: Crème sûre | F13: Varia | G13: 62 | H13: ml | K13: =VLOOKUP(A13,OPTIONS!A:C,3,FALSE)*G13 -> 1922 | L13: =TRIM(CONCATENATE(G13," ", $H13, " ", $E13)) -> 62 ml Crème sûre | M13: =TRIM(CONCATENATE(K13," ", $H13, " ", $E13)) -> 1922 ml Crème sûre | N13: =CONCATENATE(E13, " (", TRIM(H13), ")") -> Crème sûre (ml)
A14: 1 | B14: =VLOOKUP(A14,OPTIONS!A:C,2,FALSE) -> 45656 | C14: 3. Souper | D14: Fajitas | E14: Salsa | F14: Varia | G14: 80 | H14: ml | K14: =VLOOKUP(A14,OPTIONS!A:C,3,FALSE)*G14 -> 2480 | L14: =TRIM(CONCATENATE(G14," ", $H14, " ", $E14)) -> 80 ml Salsa | M14: =TRIM(CONCATENATE(K14," ", $H14, " ", $E14)) -> 2480 ml Salsa | N14: =CONCATENATE(E14, " (", TRIM(H14), ")") -> Salsa (ml)
A15: 1 | B15: =VLOOKUP(A15,OPTIONS!A:C,2,FALSE) -> 45656 | C15: 3. Souper | D15: Fajitas | E15: Olives | F15: Fruits et légumes | G15: 56 | H15: ml | K15: =VLOOKUP(A15,OPTIONS!A:C,3,FALSE)*G15 -> 1736 | L15: =TRIM(CONCATENATE(G15," ", $H15, " ", $E15)) -> 56 ml Olives | M15: =TRIM(CONCATENATE(K15," ", $H15, " ", $E15)) -> 1736 ml Olives | N15: =CONCATENATE(E15, " (", TRIM(H15), ")") -> Olives (ml)
A16: 1 | B16: =VLOOKUP(A16,OPTIONS!A:C,2,FALSE) -> 45656 | C16: 3. Souper | D16: Fajitas | E16: Tomate | F16: Fruits et légumes | G16: 0.33 | H16: unité | K16: =VLOOKUP(A16,OPTIONS!A:C,3,FALSE)*G16 -> 10.23 | L16: =TRIM(CONCATENATE(G16," ", $H16, " ", $E16)) -> 0.33 unité Tomate | M16: =TRIM(CONCATENATE(K16," ", $H16, " ", $E16)) -> 10.23 unité Tomate | N16: =CONCATENATE(E16, " (", TRIM(H16), ")") -> Tomate (unité)
A17: 1 | B17: =VLOOKUP(A17,OPTIONS!A:C,2,FALSE) -> 45656 | C17: 3. Souper | D17: Fajitas | E17: Laitue iceberg | F17: Fruits et légumes | G17: 0.125 | H17: Unité | K17: =VLOOKUP(A17,OPTIONS!A:C,3,FALSE)*G17 -> 3.875 | L17: =TRIM(CONCATENATE(G17," ", $H17, " ", $E17)) -> 0.125 Unité Laitue iceberg | M17: =TRIM(CONCATENATE(K17," ", $H17, " ", $E17)) -> 3.875 Unité Laitue iceberg | N17: =CONCATENATE(E17, " (", TRIM(H17), ")") -> Laitue iceberg (Unité)
... A26: 2 | B26: =VLOOKUP(A26,OPTIONS!A:C,2,FALSE) -> 45657 | C26: 1. Déjeuner | D26: Toast/gaufre nutella/peanut | E26: Gaufre | F26: Produits céréaliers | G26: 1 | H26: Unité | K26: =VLOOKUP(A26,OPTIONS!A:C,3,FALSE)*G26 -> 31 | L26: =TRIM(CONCATENATE(G26," ", $H26, " ", $E26)) -> 1 Unité Gaufre | M26: =TRIM(CONCATENATE(K26," ", $H26, " ", $E26)) -> 31 Unité Gaufre | N26: =CONCATENATE(E26, " (", TRIM(H26), ")") -> Gaufre (Unité)
A27: 2 | B27: =VLOOKUP(A27,OPTIONS!A:C,2,FALSE) -> 45657 | C27: 1. Déjeuner | D27: Toast/gaufre nutella/peanut | E27: Banane | F27: Fruits et légumes | G27: 0.5 | H27: Unité | K27: =VLOOKUP(A27,OPTIONS!A:C,3,FALSE)*G27 -> 15.5 | L27: =TRIM(CONCATENATE(G27," ", $H27, " ", $E27)) -> 0.5 Unité Banane | M27: =TRIM(CONCATENATE(K27," ", $H27, " ", $E27)) -> 15.5 Unité Banane | N27: =CONCATENATE(E27, " (", TRIM(H27), ")") -> Banane (Unité)
A28: 2 | B28: =VLOOKUP(A28,OPTIONS!A:C,2,FALSE) -> 45657 | C28: 1. Déjeuner | D28: Toast/gaufre nutella/peanut | E28: Fraises | F28: Fruits et légumes | G28: 4 | H28: Unité | K28: =VLOOKUP(A28,OPTIONS!A:C,3,FALSE)*G28 -> 124 | L28: =TRIM(CONCATENATE(G28," ", $H28, " ", $E28)) -> 4 Unité Fraises | M28: =TRIM(CONCATENATE(K28," ", $H28, " ", $E28)) -> 124 Unité Fraises | N28: =CONCATENATE(E28, " (", TRIM(H28), ")") -> Fraises (Unité)
A29: 2 | B29: =VLOOKUP(A29,OPTIONS!A:C,2,FALSE) -> 45657 | C29: 1. Déjeuner | D29: Toast/gaufre nutella/peanut | E29: Sirop d'érable | F29: Varia | G29: 40 | H29: ml | K29: =VLOOKUP(A29,OPTIONS!A:C,3,FALSE)*G29 -> 1240 | L29: =TRIM(CONCATENATE(G29," ", $H29, " ", $E29)) -> 40 ml Sirop d'érable | M29: =TRIM(CONCATENATE(K29," ", $H29, " ", $E29)) -> 1240 ml Sirop d'érable | N29: =CONCATENATE(E29, " (", TRIM(H29), ")") -> Sirop d'érable (ml)
A30: 2 | B30: =VLOOKUP(A30,OPTIONS!A:C,2,FALSE) -> 45657 | C30: Collation | D30: Chips | E30: Chips Type 1 | F30: Varia | G30: 40 | H30: g | K30: =VLOOKUP(A30,OPTIONS!A:C,3,FALSE)*G30 -> 1240 | L30: =TRIM(CONCATENATE(G30," ", $H30, " ", $E30)) -> 40 g Chips Type 1 | M30: =TRIM(CONCATENATE(K30," ", $H30, " ", $E30)) -> 1240 g Chips Type 1 | N30: =CONCATENATE(E30, " (", TRIM(H30), ")") -> Chips Type 1 (g)
A31: 2 | B31: =VLOOKUP(A31,OPTIONS!A:C,2,FALSE) -> 45657 | C31: Collation | D31: Chips | E31: Chips Type 2 | F31: Varia | G31: 40 | H31: g | K31: =VLOOKUP(A31,OPTIONS!A:C,3,FALSE)*G31 -> 1240 | L31: =TRIM(CONCATENATE(G31," ", $H31, " ", $E31)) -> 40 g Chips Type 2 | M31: =TRIM(CONCATENATE(K31," ", $H31, " ", $E31)) -> 1240 g Chips Type 2 | N31: =CONCATENATE(E31, " (", TRIM(H31), ")") -> Chips Type 2 (g)
A32: 2 | B32: =VLOOKUP(A32,OPTIONS!A:C,2,FALSE) -> 45657 | C32: Collation | D32: Chips | E32: Chips Type 3 | F32: Varia | G32: 40 | H32: g | K32: =VLOOKUP(A32,OPTIONS!A:C,3,FALSE)*G32 -> 1240 | L32: =TRIM(CONCATENATE(G32," ", $H32, " ", $E32)) -> 40 g Chips Type 3 | M32: =TRIM(CONCATENATE(K32," ", $H32, " ", $E32)) -> 1240 g Chips Type 3 | N32: =CONCATENATE(E32, " (", TRIM(H32), ")") -> Chips Type 3 (g)
A33: 2 | B33: =VLOOKUP(A33,OPTIONS!A:C,2,FALSE) -> 45657 | C33: Collation | D33: Chips | E33: Chips Type 4 | F33: Varia | G33: 40 | H33: g | K33: =VLOOKUP(A33,OPTIONS!A:C,3,FALSE)*G33 -> 1240 | L33: =TRIM(CONCATENATE(G33," ", $H33, " ", $E33)) -> 40 g Chips Type 4 | M33: =TRIM(CONCATENATE(K33," ", $H33, " ", $E33)) -> 1240 g Chips Type 4 | N33: =CONCATENATE(E33, " (", TRIM(H33), ")") -> Chips Type 4 (g)
A34: 2 | B34: =VLOOKUP(A34,OPTIONS!A:C,2,FALSE) -> 45657 | C34: 1. Déjeuner | D34: Pain | E34: Toasts | F34: Produits céréaliers | G34: 1.5 | H34: Unité | K34: =VLOOKUP(A34,OPTIONS!A:C,3,FALSE)*G34 -> 46.5 | L34: =TRIM(CONCATENATE(G34," ", $H34, " ", $E34)) -> 1.5 Unité Toasts | M34: =TRIM(CONCATENATE(K34," ", $H34, " ", $E34)) -> 46.5 Unité Toasts | N34: =CONCATENATE(E34, " (", TRIM(H34), ")") -> Toasts (Unité)
A35: 2 | B35: =VLOOKUP(A35,OPTIONS!A:C,2,FALSE) -> 45657 | C35: Collation | D35: Nachos | E35: Tostitos | F35: Varia | G35: 2 | H35: Sacs au total | K35: =VLOOKUP(A35,OPTIONS!A:C,3,FALSE)*G35 -> 62 | L35: =TRIM(CONCATENATE(G35," ", $H35, " ", $E35)) -> 2 Sacs au total Tostitos | M35: =TRIM(CONCATENATE(K35," ", $H35, " ", $E35)) -> 62 Sacs au total Tostitos | N35: =CONCATENATE(E35, " (", TRIM(H35), ")") -> Tostitos (Sacs au total)
A36: 2 | B36: =VLOOKUP(A36,OPTIONS!A:C,2,FALSE) -> 45657 | C36: Collation | D36: Nachos | E36: Olives tranchés | F36: Varia | G36: 0.09375 | H36: canettes | K36: =VLOOKUP(A36,OPTIONS!A:C,3,FALSE)*G36 -> 2.90625 | L36: =TRIM(CONCATENATE(G36," ", $H36, " ", $E36)) -> 0.09375 canettes Olives tranchés | M36: =TRIM(CONCATENATE(K36," ", $H36, " ", $E36)) -> 2.90625 canettes Olives tranchés | N36: =CONCATENATE(E36, " (", TRIM(H36), ")") -> Olives tranchés (canettes)
A37: 2 | B37: =VLOOKUP(A37,OPTIONS!A:C,2,FALSE) -> 45657 | C37: Collation | D37: Nachos | E37: Salsa | F37: Varia | G37: 0.03125 | H37: pot | K37: =VLOOKUP(A37,OPTIONS!A:C,3,FALSE)*G37 -> 0.96875 | L37: =TRIM(CONCATENATE(G37," ", $H37, " ", $E37)) -> 0.03125 pot Salsa | M37: =TRIM(CONCATENATE(K37," ", $H37, " ", $E37)) -> 0.96875 pot Salsa | N37: =CONCATENATE(E37, " (", TRIM(H37), ")") -> Salsa (pot)
A38: 2 | B38: =VLOOKUP(A38,OPTIONS!A:C,2,FALSE) -> 45657 | C38: Collation | D38: Nachos | E38: Crème sure | F38: Produits laitiers | G38: 0.03125 | H38: pot | K38: =VLOOKUP(A38,OPTIONS!A:C,3,FALSE)*G38 -> 0.96875 | L38: =TRIM(CONCATENATE(G38," ", $H38, " ", $E38)) -> 0.03125 pot Crème sure | M38: =TRIM(CONCATENATE(K38," ", $H38, " ", $E38)) -> 0.96875 pot Crème sure | N38: =CONCATENATE(E38, " (", TRIM(H38), ")") -> Crème sure (pot)
A39: 2 | B39: =VLOOKUP(A39,OPTIONS!A:C,2,FALSE) -> 45657 | C39: Collation | D39: Nachos | E39: Fromage rapé | F39: Produits laitiers | G39: 15 | H39: gr | K39: =VLOOKUP(A39,OPTIONS!A:C,3,FALSE)*G39 -> 465 | L39: =TRIM(CONCATENATE(G39," ", $H39, " ", $E39)) -> 15 gr Fromage rapé | M39: =TRIM(CONCATENATE(K39," ", $H39, " ", $E39)) -> 465 gr Fromage rapé | N39: =CONCATENATE(E39, " (", TRIM(H39), ")") -> Fromage rapé (gr)
... A55: 2 | B55: =VLOOKUP(A55,OPTIONS!A:C,2,FALSE) -> 45657 | C55: Collation | D55: Crudités | E55: Trempettes | F55: Varia | G55: 0.11111111 | H55: Pots | K55: =VLOOKUP(A55,OPTIONS!A:C,3,FALSE)*G55 -> 3.4444444 | L55: =TRIM(CONCATENATE(G55," ", $H55, " ", $E55)) -> 0.111111111111111 Pots Trempettes | M55: =TRIM(CONCATENATE(K55," ", $H55, " ", $E55)) -> 3.44444444444444 Pots Trempettes | N55: =CONCATENATE(E55, " (", TRIM(H55), ")") -> Trempettes (Pots)
B56: =VLOOKUP(A56,OPTIONS!A:C,2,FALSE) -> MOYENNE | K56: =VLOOKUP(A56,OPTIONS!A:C,3,FALSE)*G56 -> 0 | L56: =TRIM(CONCATENATE(G56," ", $H56, " ", $E56)) | M56: =TRIM(CONCATENATE(K56," ", $H56, " ", $E56)) -> 0 | N56: =CONCATENATE(E56, " (", TRIM(H56), ")") -> ()
B57: =VLOOKUP(A57,OPTIONS!A:C,2,FALSE) -> MOYENNE | K57: =VLOOKUP(A57,OPTIONS!A:C,3,FALSE)*G57 -> 0 | L57: =TRIM(CONCATENATE(G57," ", $H57, " ", $E57)) | M57: =TRIM(CONCATENATE(K57," ", $H57, " ", $E57)) -> 0 | N57: =CONCATENATE(E57, " (", TRIM(H57), ")") -> ()
B58: =VLOOKUP(A58,OPTIONS!A:C,2,FALSE) -> MOYENNE | K58: =VLOOKUP(A58,OPTIONS!A:C,3,FALSE)*G58 -> 0 | L58: =TRIM(CONCATENATE(G58," ", $H58, " ", $E58)) | M58: =TRIM(CONCATENATE(K58," ", $H58, " ", $E58)) -> 0 | N58: =CONCATENATE(E58, " (", TRIM(H58), ")") -> ()
B59: =VLOOKUP(A59,OPTIONS!A:C,2,FALSE) -> MOYENNE | K59: =VLOOKUP(A59,OPTIONS!A:C,3,FALSE)*G59 -> 0 | L59: =TRIM(CONCATENATE(G59," ", $H59, " ", $E59)) | M59: =TRIM(CONCATENATE(K59," ", $H59, " ", $E59)) -> 0 | N59: =CONCATENATE(E59, " (", TRIM(H59), ")") -> ()
B60: =VLOOKUP(A60,OPTIONS!A:C,2,FALSE) -> MOYENNE | K60: =VLOOKUP(A60,OPTIONS!A:C,3,FALSE)*G60 -> 0 | L60: =TRIM(CONCATENATE(G60," ", $H60, " ", $E60)) | M60: =TRIM(CONCATENATE(K60," ", $H60, " ", $E60)) -> 0 | N60: =CONCATENATE(E60, " (", TRIM(H60), ")") -> ()
B61: =VLOOKUP(A61,OPTIONS!A:C,2,FALSE) -> MOYENNE | K61: =VLOOKUP(A61,OPTIONS!A:C,3,FALSE)*G61 -> 0 | L61: =TRIM(CONCATENATE(G61," ", $H61, " ", $E61)) | M61: =TRIM(CONCATENATE(K61," ", $H61, " ", $E61)) -> 0 | N61: =CONCATENATE(E61, " (", TRIM(H61), ")") -> ()
B62: =VLOOKUP(A62,OPTIONS!A:C,2,FALSE) -> MOYENNE | K62: =VLOOKUP(A62,OPTIONS!A:C,3,FALSE)*G62 -> 0 | L62: =TRIM(CONCATENATE(G62," ", $H62, " ", $E62)) | M62: =TRIM(CONCATENATE(K62," ", $H62, " ", $E62)) -> 0 | N62: =CONCATENATE(E62, " (", TRIM(H62), ")") -> ()
B63: =VLOOKUP(A63,OPTIONS!A:C,2,FALSE) -> MOYENNE | K63: =VLOOKUP(A63,OPTIONS!A:C,3,FALSE)*G63 -> 0 | L63: =TRIM(CONCATENATE(G63," ", $H63, " ", $E63)) | M63: =TRIM(CONCATENATE(K63," ", $H63, " ", $E63)) -> 0 | N63: =CONCATENATE(E63, " (", TRIM(H63), ")") -> ()
...

Sheet INVENTAIRE CENTRE
A1: Liste des aliments disponible au centre
A2: Exemple:
A3: 1 boite de sel
A4: 1L de nesquik
A5: 500g de poudre nesquik
A6: 1 gros pot de confiture au fraise
A7: 300g (120 biscuits) soda et 225g de biscuit breton

Sheet MENU VISUEL
B1: VENDREDI | C1: SAMEDI | D1: DIMANCHE | E1: LUNDI
A2: DÉJEUNER | C2: bagels with philadelphia +jus/milk | D2: toast/ waffle nutella/ peanut
A3: DÎNER | C3: pasta salad | D3: sandwiches ham + jus
A4: Collation #1 | C4: pomme + fromage petit quebec | D4: cookies
A5: SOUPER | C5: tacos +jus+ ris espagnol
A6: Collation #2 | B6: smores | C6: rice crispy

Sheet MENU
A1: DATE | B1: REPAS | C1: PLAT | D1: POUR GROUPE
A2: MOYENNE | B2: 0. Autre | C2: Café instantané | D2: 1 Boîte Café instantané
C3: Poivre | D3: 1 Boîte Poivre
C4: Sel | D4: 1 Boîte Sel
C5: Sucre | D5: 1 Boîte Sucre
B6: (blank) | C6: (blank) | D6: 0
A7: 45657 | B7: 2. Diner | C7: Charcuterie | D7: 930 g Jambon
D8: 930 g Salami
D9: 930 g Mortadelle
D10: 930 g Poulet
C11: Chips | D11: 3.44444444444444 Sacs Chips
C12: Jus | D12: 0.96875 Pot Jus en poudre
B13: 3. Souper | C13: Macaronis avec boulettes | D13: 1860 ml Macaroni
C14: Patates grecques | D14: 6200 g Petites patates
C15: Salade César | D15: 6.2 Unité Laitues iceberg
D16: 1550 g Croutons
D17: 620 ml Vignaigrette César
D18: 0.62 Unité Bacon émietté (sac)
B19: 1. Déjeuner | C19: Œufs durs | D19: 37.2 unité Œufs
C20: Toast/gaufre nutella/peanut | D20: 31 Unité Toasts
D21: 620 ml Peanut butter
D22: 620 ml Nutella
D23: 31 Unité Gaufre
D24: 15.5 Unité Banane
D25: 124 Unité Fraises
D26: 1240 ml Sirop d'érable
C27: Pain | D27: 46.5 Unité Toasts
B28: Collation | C28: Chips | D28: 1240 g Chips Type 1
D29: 1240 g Chips Type 2
D30: 1240 g Chips Type 3
D31: 1240 g Chips Type 4
C32: Nachos | D32: 62 Sacs au total Tostitos
D33: 2.90625 canettes Olives tranchés
D34: 0.96875 pot Salsa
D35: 0.96875 pot Crème sure
D36: 465 gr Fromage rapé
D37: 1550 g Fromage râpé
D38: 15.5 Unité Échalotes (oignons verts)
D39: 10.3333333333333 Unité Avocat
D40: 103.333333333333 g Coriandre fraîche
...

Sheet LISTE D'ÉPICERIE
A1: ÉPICERIE? | B1: (All) | F1: ÉPICERIE? | G1: (All)
A2: CENTRE? | B2: (All) | F2: CENTRE? | G2: (All)
A4: SECTION | B4: POUR GROUPE | F4: SECTION | G4: POUR GROUPE
A5: Varia | B5: 1 Boîte Café instantané | F5: Varia | G5: 1 Boîte Café instantané
B6: 1 Boîte Poivre | G6: 1 Boîte Poivre
B7: 1 Boîte Sel | G7: 1 Boîte Sel
B8: 1 Boîte Sucre | G8: 1 Boîte Sucre
B9: 3.44444444444444 Sacs Chips | G9: 3.44444444444444 Sacs Chips
B10: 1922 ml Crème sûre | G10: 1922 ml Crème sûre
B11: 2480 ml Salsa | G11: 2480 ml Salsa
B12: 620 ml Peanut butter | G12: 620 ml Peanut butter
B13: 620 ml Nutella | G13: 620 ml Nutella
B14: 1240 ml Sirop d'érable | G14: 1240 ml Sirop d'érable
B15: 1240 g Chips Type 1 | G15: 1240 g Chips Type 1
B16: 1240 g Chips Type 2 | G16: 1240 g Chips Type 2
B17: 1240 g Chips Type 3 | G17: 1240 g Chips Type 3
... B25: 3.44444444444444 Pots Trempettes | G25: 3.44444444444444 Pots Trempettes
A26: (blank) | B26: 0 | F26: (blank) | G26: 0
A27: Produits céréaliers | B27: 77.5 unité Tortillas | F27: Produits céréaliers | G27: 77.5 unité Tortillas
B28: 31 Unité Toasts | G28: 31 Unité Toasts
B29: 31 Unité Gaufre | G29: 31 Unité Gaufre
B30: 46.5 Unité Toasts | G30: 46.5 Unité Toasts
B31: 1860 ml Macaroni | G31: 1860 ml Macaroni
A32: Fruits et légumes | B32: 1736 ml Olives | F32: Fruits et légumes | G32: 1736 ml Olives
B33: 10.23 unité Tomate | G33: 10.23 unité Tomate
B34: 3.875 Unité Laitue iceberg | G34: 3.875 Unité Laitue iceberg
B35: 4.65 unité Oignon rouge | G35: 4.65 unité Oignon rouge
B36: 4.65 unité Poivron jaune | G36: 4.65 unité Poivron jaune
B37: 4.65 unité Poivron rouge | G37: 4.65 unité Poivron rouge
B38: 15.5 Unité Banane | G38: 15.5 Unité Banane
B39: 124 Unité Fraises | G39: 124 Unité Fraises
B40: 15.5 Unité Échalotes (oignons verts) | G40: 15.5 Unité Échalotes (oignons verts)
B41: 10.3333333333333 Unité Avocat | G41: 10.3333333333333 Unité Avocat
B42: 103.333333333333 g Coriandre fraîche | G42: 103.333333333333 g Coriandre fraîche
B43: 5.16666666666667 Unité Lime | G43: 5.16666666666667 Unité Lime
B44: 6200 g Petites patates | G44: 6200 g Petites patates
... B48: 9.3 Unité Concombre anglais | G48: 9.3 Unité Concombre anglais
A49: Viandes | B49: 930 g Jambon | F49: Viandes | G49: 930 g Jambon
B50: 930 g Salami | G50: 930 g Salami
B51: 930 g Mortadelle | G51: 930 g Mortadelle
...
